2024-12-18 09:17:19,139 - ERROR - Exception on /admin/country/ [GET]
Traceback (most recent call last):
  File "/Users/sea/Documents/dev/superapp/venv/lib/python3.9/site-packages/mysql/connector/connection_cext.py", line 706, in cmd_query
    self._cmysql.query(
_mysql_connector.MySQLInterfaceError: Unknown column 'songCountry.url' in 'field list'

The above exception was the direct cause of the following exception:

Traceback (most recent call last):
  File "/Users/sea/Documents/dev/superapp/venv/lib/python3.9/site-packages/sqlalchemy/engine/base.py", line 1967, in _exec_single_context
    self.dialect.do_execute(
  File "/Users/sea/Documents/dev/superapp/venv/lib/python3.9/site-packages/sqlalchemy/engine/default.py", line 941, in do_execute
    cursor.execute(statement, parameters)
  File "/Users/sea/Documents/dev/superapp/venv/lib/python3.9/site-packages/mysql/connector/cursor_cext.py", line 357, in execute
    result = self._connection.cmd_query(
  File "/Users/sea/Documents/dev/superapp/venv/lib/python3.9/site-packages/mysql/connector/opentelemetry/context_propagation.py", line 97, in wrapper
    return method(cnx, *args, **kwargs)
  File "/Users/sea/Documents/dev/superapp/venv/lib/python3.9/site-packages/mysql/connector/connection_cext.py", line 714, in cmd_query
    raise get_mysql_exception(
mysql.connector.errors.ProgrammingError: 1054 (42S22): Unknown column 'songCountry.url' in 'field list'

The above exception was the direct cause of the following exception:

Traceback (most recent call last):
  File "/Users/sea/Documents/dev/superapp/venv/lib/python3.9/site-packages/flask/app.py", line 1511, in wsgi_app
    response = self.full_dispatch_request()
  File "/Users/sea/Documents/dev/superapp/venv/lib/python3.9/site-packages/flask/app.py", line 919, in full_dispatch_request
    rv = self.handle_user_exception(e)
  File "/Users/sea/Documents/dev/superapp/venv/lib/python3.9/site-packages/flask/app.py", line 917, in full_dispatch_request
    rv = self.dispatch_request()
  File "/Users/sea/Documents/dev/superapp/venv/lib/python3.9/site-packages/flask/app.py", line 902, in dispatch_request
    return self.ensure_sync(self.view_functions[rule.endpoint])(**view_args)  # type: ignore[no-any-return]
  File "/Users/sea/Documents/dev/superapp/venv/lib/python3.9/site-packages/flask_admin/base.py", line 69, in inner
    return self._run_view(f, *args, **kwargs)
  File "/Users/sea/Documents/dev/superapp/venv/lib/python3.9/site-packages/flask_admin/base.py", line 369, in _run_view
    return fn(self, *args, **kwargs)
  File "/Users/sea/Documents/dev/superapp/venv/lib/python3.9/site-packages/flask_admin/model/base.py", line 1980, in index_view
    count, data = self.get_list(view_args.page, sort_column, view_args.sort_desc,
  File "/Users/sea/Documents/dev/superapp/venv/lib/python3.9/site-packages/flask_admin/contrib/sqla/view.py", line 1100, in get_list
    query = query.all()
  File "/Users/sea/Documents/dev/superapp/venv/lib/python3.9/site-packages/sqlalchemy/orm/query.py", line 2673, in all
    return self._iter().all()  # type: ignore
  File "/Users/sea/Documents/dev/superapp/venv/lib/python3.9/site-packages/sqlalchemy/orm/query.py", line 2827, in _iter
    result: Union[ScalarResult[_T], Result[_T]] = self.session.execute(
  File "/Users/sea/Documents/dev/superapp/venv/lib/python3.9/site-packages/sqlalchemy/orm/session.py", line 2362, in execute
    return self._execute_internal(
  File "/Users/sea/Documents/dev/superapp/venv/lib/python3.9/site-packages/sqlalchemy/orm/session.py", line 2247, in _execute_internal
    result: Result[Any] = compile_state_cls.orm_execute_statement(
  File "/Users/sea/Documents/dev/superapp/venv/lib/python3.9/site-packages/sqlalchemy/orm/context.py", line 305, in orm_execute_statement
    result = conn.execute(
  File "/Users/sea/Documents/dev/superapp/venv/lib/python3.9/site-packages/sqlalchemy/engine/base.py", line 1418, in execute
    return meth(
  File "/Users/sea/Documents/dev/superapp/venv/lib/python3.9/site-packages/sqlalchemy/sql/elements.py", line 515, in _execute_on_connection
    return connection._execute_clauseelement(
  File "/Users/sea/Documents/dev/superapp/venv/lib/python3.9/site-packages/sqlalchemy/engine/base.py", line 1640, in _execute_clauseelement
    ret = self._execute_context(
  File "/Users/sea/Documents/dev/superapp/venv/lib/python3.9/site-packages/sqlalchemy/engine/base.py", line 1846, in _execute_context
    return self._exec_single_context(
  File "/Users/sea/Documents/dev/superapp/venv/lib/python3.9/site-packages/sqlalchemy/engine/base.py", line 1986, in _exec_single_context
    self._handle_dbapi_exception(
  File "/Users/sea/Documents/dev/superapp/venv/lib/python3.9/site-packages/sqlalchemy/engine/base.py", line 2355, in _handle_dbapi_exception
    raise sqlalchemy_exception.with_traceback(exc_info[2]) from e
  File "/Users/sea/Documents/dev/superapp/venv/lib/python3.9/site-packages/sqlalchemy/engine/base.py", line 1967, in _exec_single_context
    self.dialect.do_execute(
  File "/Users/sea/Documents/dev/superapp/venv/lib/python3.9/site-packages/sqlalchemy/engine/default.py", line 941, in do_execute
    cursor.execute(statement, parameters)
  File "/Users/sea/Documents/dev/superapp/venv/lib/python3.9/site-packages/mysql/connector/cursor_cext.py", line 357, in execute
    result = self._connection.cmd_query(
  File "/Users/sea/Documents/dev/superapp/venv/lib/python3.9/site-packages/mysql/connector/opentelemetry/context_propagation.py", line 97, in wrapper
    return method(cnx, *args, **kwargs)
  File "/Users/sea/Documents/dev/superapp/venv/lib/python3.9/site-packages/mysql/connector/connection_cext.py", line 714, in cmd_query
    raise get_mysql_exception(
sqlalchemy.exc.ProgrammingError: (mysql.connector.errors.ProgrammingError) 1054 (42S22): Unknown column 'songCountry.url' in 'field list'
[SQL: SELECT `songCountry`.`countryID` AS `songCountry_countryID`, `songCountry`.country AS `songCountry_country`, `songCountry`.image AS `songCountry_image`, `songCountry`.url AS `songCountry_url`, `songCountry`.status AS `songCountry_status`, `songCountry`.display_order AS `songCountry_display_order` 
FROM `songCountry` ORDER BY `songCountry`.display_order DESC 
 LIMIT %(param_1)s]
[parameters: {'param_1': 20}]
(Background on this error at: https://sqlalche.me/e/20/f405)
2024-12-18 10:16:41,731 - ERROR - Exception on /admin/songshow/ [GET]
Traceback (most recent call last):
  File "/Users/sea/Documents/dev/superapp/venv/lib/python3.9/site-packages/mysql/connector/connection_cext.py", line 706, in cmd_query
    self._cmysql.query(
_mysql_connector.MySQLInterfaceError: Table 'superagency.songshows' doesn't exist

The above exception was the direct cause of the following exception:

Traceback (most recent call last):
  File "/Users/sea/Documents/dev/superapp/venv/lib/python3.9/site-packages/sqlalchemy/engine/base.py", line 1967, in _exec_single_context
    self.dialect.do_execute(
  File "/Users/sea/Documents/dev/superapp/venv/lib/python3.9/site-packages/sqlalchemy/engine/default.py", line 941, in do_execute
    cursor.execute(statement, parameters)
  File "/Users/sea/Documents/dev/superapp/venv/lib/python3.9/site-packages/mysql/connector/cursor_cext.py", line 357, in execute
    result = self._connection.cmd_query(
  File "/Users/sea/Documents/dev/superapp/venv/lib/python3.9/site-packages/mysql/connector/opentelemetry/context_propagation.py", line 97, in wrapper
    return method(cnx, *args, **kwargs)
  File "/Users/sea/Documents/dev/superapp/venv/lib/python3.9/site-packages/mysql/connector/connection_cext.py", line 714, in cmd_query
    raise get_mysql_exception(
mysql.connector.errors.ProgrammingError: 1146 (42S02): Table 'superagency.songshows' doesn't exist

The above exception was the direct cause of the following exception:

Traceback (most recent call last):
  File "/Users/sea/Documents/dev/superapp/venv/lib/python3.9/site-packages/flask/app.py", line 1511, in wsgi_app
    response = self.full_dispatch_request()
  File "/Users/sea/Documents/dev/superapp/venv/lib/python3.9/site-packages/flask/app.py", line 919, in full_dispatch_request
    rv = self.handle_user_exception(e)
  File "/Users/sea/Documents/dev/superapp/venv/lib/python3.9/site-packages/flask/app.py", line 917, in full_dispatch_request
    rv = self.dispatch_request()
  File "/Users/sea/Documents/dev/superapp/venv/lib/python3.9/site-packages/flask/app.py", line 902, in dispatch_request
    return self.ensure_sync(self.view_functions[rule.endpoint])(**view_args)  # type: ignore[no-any-return]
  File "/Users/sea/Documents/dev/superapp/venv/lib/python3.9/site-packages/flask_admin/base.py", line 69, in inner
    return self._run_view(f, *args, **kwargs)
  File "/Users/sea/Documents/dev/superapp/venv/lib/python3.9/site-packages/flask_admin/base.py", line 369, in _run_view
    return fn(self, *args, **kwargs)
  File "/Users/sea/Documents/dev/superapp/venv/lib/python3.9/site-packages/flask_admin/model/base.py", line 1980, in index_view
    count, data = self.get_list(view_args.page, sort_column, view_args.sort_desc,
  File "/Users/sea/Documents/dev/superapp/venv/lib/python3.9/site-packages/flask_admin/contrib/sqla/view.py", line 1086, in get_list
    count = count_query.scalar() if count_query else None
  File "/Users/sea/Documents/dev/superapp/venv/lib/python3.9/site-packages/sqlalchemy/orm/query.py", line 2805, in scalar
    ret = self.one()
  File "/Users/sea/Documents/dev/superapp/venv/lib/python3.9/site-packages/sqlalchemy/orm/query.py", line 2778, in one
    return self._iter().one()  # type: ignore
  File "/Users/sea/Documents/dev/superapp/venv/lib/python3.9/site-packages/sqlalchemy/orm/query.py", line 2827, in _iter
    result: Union[ScalarResult[_T], Result[_T]] = self.session.execute(
  File "/Users/sea/Documents/dev/superapp/venv/lib/python3.9/site-packages/sqlalchemy/orm/session.py", line 2362, in execute
    return self._execute_internal(
  File "/Users/sea/Documents/dev/superapp/venv/lib/python3.9/site-packages/sqlalchemy/orm/session.py", line 2247, in _execute_internal
    result: Result[Any] = compile_state_cls.orm_execute_statement(
  File "/Users/sea/Documents/dev/superapp/venv/lib/python3.9/site-packages/sqlalchemy/orm/context.py", line 305, in orm_execute_statement
    result = conn.execute(
  File "/Users/sea/Documents/dev/superapp/venv/lib/python3.9/site-packages/sqlalchemy/engine/base.py", line 1418, in execute
    return meth(
  File "/Users/sea/Documents/dev/superapp/venv/lib/python3.9/site-packages/sqlalchemy/sql/elements.py", line 515, in _execute_on_connection
    return connection._execute_clauseelement(
  File "/Users/sea/Documents/dev/superapp/venv/lib/python3.9/site-packages/sqlalchemy/engine/base.py", line 1640, in _execute_clauseelement
    ret = self._execute_context(
  File "/Users/sea/Documents/dev/superapp/venv/lib/python3.9/site-packages/sqlalchemy/engine/base.py", line 1846, in _execute_context
    return self._exec_single_context(
  File "/Users/sea/Documents/dev/superapp/venv/lib/python3.9/site-packages/sqlalchemy/engine/base.py", line 1986, in _exec_single_context
    self._handle_dbapi_exception(
  File "/Users/sea/Documents/dev/superapp/venv/lib/python3.9/site-packages/sqlalchemy/engine/base.py", line 2355, in _handle_dbapi_exception
    raise sqlalchemy_exception.with_traceback(exc_info[2]) from e
  File "/Users/sea/Documents/dev/superapp/venv/lib/python3.9/site-packages/sqlalchemy/engine/base.py", line 1967, in _exec_single_context
    self.dialect.do_execute(
  File "/Users/sea/Documents/dev/superapp/venv/lib/python3.9/site-packages/sqlalchemy/engine/default.py", line 941, in do_execute
    cursor.execute(statement, parameters)
  File "/Users/sea/Documents/dev/superapp/venv/lib/python3.9/site-packages/mysql/connector/cursor_cext.py", line 357, in execute
    result = self._connection.cmd_query(
  File "/Users/sea/Documents/dev/superapp/venv/lib/python3.9/site-packages/mysql/connector/opentelemetry/context_propagation.py", line 97, in wrapper
    return method(cnx, *args, **kwargs)
  File "/Users/sea/Documents/dev/superapp/venv/lib/python3.9/site-packages/mysql/connector/connection_cext.py", line 714, in cmd_query
    raise get_mysql_exception(
sqlalchemy.exc.ProgrammingError: (mysql.connector.errors.ProgrammingError) 1146 (42S02): Table 'superagency.songshows' doesn't exist
[SQL: SELECT count(%(count_2)s) AS count_1 
FROM `songShows`]
[parameters: {'count_2': '*'}]
(Background on this error at: https://sqlalche.me/e/20/f405)
2024-12-24 10:39:01,224 - ERROR - Exception on / [GET]
Traceback (most recent call last):
  File "/Users/sea/Documents/dev/superapp/venv/lib/python3.9/site-packages/flask/app.py", line 1511, in wsgi_app
    response = self.full_dispatch_request()
  File "/Users/sea/Documents/dev/superapp/venv/lib/python3.9/site-packages/flask/app.py", line 919, in full_dispatch_request
    rv = self.handle_user_exception(e)
  File "/Users/sea/Documents/dev/superapp/venv/lib/python3.9/site-packages/flask/app.py", line 917, in full_dispatch_request
    rv = self.dispatch_request()
  File "/Users/sea/Documents/dev/superapp/venv/lib/python3.9/site-packages/flask/app.py", line 902, in dispatch_request
    return self.ensure_sync(self.view_functions[rule.endpoint])(**view_args)  # type: ignore[no-any-return]
  File "/Users/sea/Documents/dev/superapp/app.py", line 150, in home
    return render_template('home.html', greeting=greeting, title="Home")
  File "/Users/sea/Documents/dev/superapp/venv/lib/python3.9/site-packages/flask/templating.py", line 149, in render_template
    template = app.jinja_env.get_or_select_template(template_name_or_list)
  File "/Users/sea/Documents/dev/superapp/venv/lib/python3.9/site-packages/jinja2/environment.py", line 1084, in get_or_select_template
    return self.get_template(template_name_or_list, parent, globals)
  File "/Users/sea/Documents/dev/superapp/venv/lib/python3.9/site-packages/jinja2/environment.py", line 1013, in get_template
    return self._load_template(name, globals)
  File "/Users/sea/Documents/dev/superapp/venv/lib/python3.9/site-packages/jinja2/environment.py", line 972, in _load_template
    template = self.loader.load(self, name, self.make_globals(globals))
  File "/Users/sea/Documents/dev/superapp/venv/lib/python3.9/site-packages/jinja2/loaders.py", line 126, in load
    source, filename, uptodate = self.get_source(environment, name)
  File "/Users/sea/Documents/dev/superapp/venv/lib/python3.9/site-packages/flask/templating.py", line 65, in get_source
    return self._get_source_fast(environment, template)
  File "/Users/sea/Documents/dev/superapp/venv/lib/python3.9/site-packages/flask/templating.py", line 99, in _get_source_fast
    raise TemplateNotFound(template)
jinja2.exceptions.TemplateNotFound: home.html
